Workbook
Name Total: '3D8DE36231C'!$C$3
Name Title: Split!$D$1
Name SelectedMainCurrencySymbol: Split!$H$2
Name ExplicitPayers: '3D8DE36231C'!$C$4
Name EffectiveCurrencySymbol: '3D8DE36231C'!$F$1
Name ExplicitPayers: Expenses!$C$4
Name SelectedMainCurrencyAbbr: Split!$G$2
Name Total: Expenses!$C$3
Name EffectiveCurrencySymbol: Expenses!$F$1
Name EffectiveCurrencySymbol: #REF!
Name EffectiveMainCurrencySymbol: Split!$J$2
Name SPLITSHEET_COL: LAMBDA(cols, Offset(cols,9,0,Rows(cols)-9))
Name EXPAND_TO_LAST_ROW: LAMBDA(range, Offset(range,0,0,Rows(Split!$A:$A)-Row(range)+1))
Name EXPAND_TO_LAST_NAME_COL: LAMBDA(arg, LET( c, COLUMN(arg), w, MAX(IF(LEN(Split!$M$7:$7), COLUMN(Split!$M$7:$7) - c + 1)), OFFSET(arg, 0, 0, , If(w=0,1,w)) ))
Name LAST_ROW: LAMBDA(range, ArrayFormula(max(if(len(range),row(range)))))
Name JSON_PROP: LAMBDA(name, value, wrapinquotes, IF( wrapInQuotes, """" & JSON_ESCAPE(name) & """:""" & JSON_ESCAPE(value) & """", """" & JSON_ESCAPE(name) & """:" & TO_TEXT(value) ))
Name EXPENSESHEET_COL: LAMBDA(cols, Offset(cols,9,0,Rows(cols)-9))
Name ADD_EMPTY_ROW: LAMBDA(array, {MAKEARRAY(1,Columns(array),LAMBDA(r,c,));array})

Sheet Split
A1: Help | D1: Copy of Blank
A2: =Round(Sum(SPLITSHEET_COL($E:$F)),2) -> 0 | E2: (USD) US Dollar | F2: main currency: | G2: =IFERROR(__xludf.DUMMYFUNCTION("IfError(REGEXEXTRACT(E2,""^\((\w{3})\)""),)"),"USD") -> USD | H2: {=If(IsBlank(G2),,Xlookup(G2,Currencies!B:B,Currencies!C:C))} -> $ | I2: applied currency: | J2: =IFERROR(__xludf.DUMMYFUNCTION("RegExExtract(TO_TEXT(K2),""^\s*([^0-9\s]+)\s*\d{1,3}(?:,\d{3})*\.\d{2}"")"),"$") -> $ | K2: 0 | M2: =IFERROR(__xludf.DUMMYFUNCTION("ARRAYFORMULA( LET( headers, EXPAND_TO_LAST_NAME_COL(M7), groupsRaw, EXPAND_TO_LAST_NAME_COL(M6), balancesRaw, EXPAND_TO_LAST_NAME_COL(M5), hasGroupError, SUMPRODUCT(N(ISERROR(groupsRaw))) > 0, hasBalanceError, SUMPRODUCT"&"(N(ISERROR(balancesRaw))) > 0, IF( (hasBalanceError+H3+NOT(A2))>0, , LET( balances, ROUND(balancesRaw, 2), groups, groupsRaw, step, 0.01, isPaidBySpecified, SUM(SPLITSHEET_COL(I:I)) > 0, "&" errTotal, IF(isPaidBySpecified, SUM(balances), SUM(balances) - $A2), grp, IF(OR(hasGroupError,COUNTA(groups) = 0), IF(headers <> """", ""ALL"", """"), groups), baseCandidates, FILTER( TRIM(People!B:B), "&" TRIM(People!B:B) <> """", ISNUMBER(MATCH(TRIM(People!B:B), headers, 0)) ), adj, MAP( headers, grp, LAMBDA(h, g, LET( groupHeaders, FILTER(headers, grp = g), "&" groupCandidates, FILTER( baseCandidates, ISNUMBER(MATCH(baseCandidates, groupHeaders, 0)), XLOOKUP(baseCandidates, headers, balances) <> 0 ), "&" err, IF(isPaidBySpecified, SUM(FILTER(balances, grp = g)), errTotal), k, MIN(ABS(ROUND(err / step, 0)), COUNTA(groupCandidates)), pos, IFERROR(MATCH(h, groupCandidates, 0), 1000000000), IF(err"&" = 0, 0, IF(pos <= k, -SIGN(err) * step, 0)) ) ) ), ROUND(balances + adj, 2) ) ) ) ) "),"")
A3: =IFERROR(__xludf.DUMMYFUNCTION("LET( isBaseCurrencyMissing, IsBlank(E2), isAddingNewCheckSheet, Not(IsBlank($A$8)), isChangingCurrency, H2 <> EffectiveMainCurrencySymbol, isProcessingRowValueChanges, $K$8<>0, noneNames, COUNTA(SPLITSHEET_COL($C:$C))=0, itemPriceMissing, COUN"&"TIFS(SPLITSHEET_COL($D:$D), ""<>"", SPLITSHEET_COL($E:$E), ""="")>0, payerAlreadyInCheck, COUNTIF( BYROW( ArrayFormula(EXPAND_TO_LAST_NAME_COL(SPLITSHEET_COL(M:M))), LAMBDA(splitRow, LET( rowNum, INDEX(ROW"&"(splitRow), 1), payRatios, ArrayFormula(MOD(splitRow,1)*10), explicitAssignments, INDIRECT(REGEXREPLACE(INDIRECT(""$C$""&rowNum), ""F\d+$"", ""ExplicitPayers"")), AND(NOT(ISBLANK(explicitAssignments)), SUM(payRatios)>0,"&" TRIM(INDIRECT(""$D$""&rowNum))<>"""") ) ) ), TRUE )>0, paidByMissing, H3, shareValuesMissing, CountIf(ArrayFormula(ERROR.TYPE($H13:H17)=2),true)>0, message,SWITCH(TRUE, isBaseCurrencyMissing, ""Select a Base Cu"&"rrency"", isAddingNewCheckSheet, ""⏳ Adding new Expense Sheet..."", isChangingCurrency,""⏳ Changing Currency Symbol..."", noneNames, ""✏️Start with the People sheet & the Expenses sheet"", itemPriceMissing,""Item(s) Amount Missing"", "&" payerAlreadyInCheck, ""Payer(s) already specified in Expense Sheet"", shareValuesMissing, ""Missing Share Values"", paidByMissing, ""Missing Payer for Item(s)"", """" ), message )"),"✏️Start with the People sheet & the Expenses sheet") -> ✏️Start with the People sheet & the Expenses sheet | F3: 1st bill row: | G3: =10 -> 10 | H3: =AND(I9>0, COUNTIFS(SPLITSHEET_COL($I:$I),"=0", SPLITSHEET_COL($F:$F),"<>")>0) -> FALSE | I3: {=OR(Map(GETSHEETNAMES(D9,TRUE),Lambda(it,IsError(Indirect(it&"!A2")))))} -> FALSE | K3: rightmost share value column number: | L3: {=MAX(Let(range,EXPAND_TO_LAST_ROW(M7:V7),IF(IsBlank(range),13, COLUMN(range))))} -> 13
L4: {=Columns(EXPAND_TO_LAST_NAME_COL(M7))} -> 1
L5: =IFERROR(__xludf.DUMMYFUNCTION("LET( sheetProp, MAP( VSTACK(""3D8DE36231C"", GETSHEETNAMES(D9, TRUE)), LAMBDA( sheetName, LET( d2Ref, IFERROR(INDIRECT(sheetName & ""!D2""), """"), effectiveCurrencySymbol2, IFERROR(INDIRECT(sheetName & ""!Effective"&"CurrencySymbol""), """"), selectedCurrencySymbol2, IFERROR(INDIRECT(sheetName & ""!E1""), """"), hasRedFormatting, INDIRECT(sheetName & ""!F3""), b2HasError, ISERROR(INDIRECT(sheetName & ""!B2"")), isRateRowHidden, INDIRECT"&"(sheetName & ""!F2""), taxVal, TO_TEXT(INDIRECT(sheetName & ""!C5"")), tipVal, TO_TEXT(INDIRECT(sheetName & ""!C6"")), discVal, TO_TEXT(INDIRECT(sheetName & ""!C7"")), IF( d2Ref = """", """", L"&"ET( includeIfCurrency, LAMBDA(rowNum, IF(OR(NOT(REGEXMATCH(TO_TEXT(INDIRECT(sheetName & ""!C"" & rowNum)), ""^[%0-9\.]*$"")),rowNum=""""), """"""C"" & rowNum & """""""", )), ranges, TEXTJOIN( "","", "&" TRUE, """"""C3"""""", """"""C"" & G3 & "":C"""""", includeIfCurrency(5), includeIfCurrency(6), includeIfCurrency(7) ), taxTipDiscValues"&", ""["""""" & TEXTJOIN("""""","""""", FALSE, JSON_ESCAPE(taxVal), JSON_ESCAPE(tipVal), JSON_ESCAPE(discVal)) & """"""]"", """""""" & JSON_ESCAPE(sheetName) & """""":{"" & TEXTJOIN( "","", "&" FALSE, JSON_PROP(""name"", sheetName, TRUE), JSON_PROP(""isDefaultCurrency"", IF(d2Ref, ""true"", ""false""), FALSE), JSON_PROP(""effectiveCurrencySymbol"", effectiveCurrencySymbol2, TRUE), "&" JSON_PROP(""selectedCurrencySymbol"", selectedCurrencySymbol2, TRUE), JSON_PROP(""hasUserOverriddenRate"", IF(b2HasError, ""true"", ""false""), FALSE), JSON_PROP(""isRateRowHidden"", IF(isRateRowHidden, ""true"", ""fals"&"e""), FALSE), JSON_PROP(""hasRedFormattingActive"", IF(hasRedFormatting, ""true"", ""false""), FALSE), JSON_PROP(""currencyFormatRanges"", ""["" & ranges & ""]"", FALSE), JSON_PROP(""taxTipDiscValues"", taxT"&"ipDiscValues, FALSE), JSON_PROP(""splitSheetRows"", GET_SHEET_RANGE(sheetName), FALSE) ) & ""}"" ) ) ) ) ), sheetObject, ""{"" & TEXTJOIN("","", TRUE, sheetProp) & ""}"", ""{"" "&" & TEXTJOIN( "","", FALSE, JSON_PROP(""mainCurrencySymbol"", EffectiveMainCurrencySymbol, TRUE), JSON_PROP(""selectedMainCurrencySymbol"", SelectedMainCurrencySymbol, TRUE), JSON_PROP(""splitSheetTitle"", Title, TR"&"UE), JSON_PROP(""maxRows"", Rows(A:A), FALSE), JSON_PROP(""maxColumns"", Columns(1:1), FALSE), JSON_PROP(""maxColWithData"", L3, FALSE), JSON_PROP(""isSheetsFormulaStale"", IF(I3, ""true"", ""false""), FALSE), JSON_"&"PROP( ""people"", ""{"" & TEXTJOIN( "","", FALSE, JSON_PROP(""namesSnapshot"", If(IsBlank(People!B1),""[]"",People!B1), FALSE), JSON_PROP( """&"currentNames"", LET( lastRow, LAST_ROW(People!A:A), items, IF(lastRow=1,, INDEX(People!A:A, 2):INDEX(People!A:A, lastRow)), If(lastRow=1,""[]"",""["" & TEXTJOIN("","", TRUE, MAP"&"(items, LAMBDA(x, """""""" & JSON_ESCAPE(x) & """"""""))) & ""]"") ), FALSE ) ) & ""}"", FALSE ), JSON_PROP(""sheets"", sheetObject, FALSE) ) "&" & ""}"" )"),"{""mainCurrencySymbol"":""$"",""selectedMainCurrencySymbol"":""$"",""splitSheetTitle"":""Copy of Blank"",""maxRows"":17,""maxColumns"":22,""maxColWithData"":13,""isSheetsFormulaStale"":false,""people"":{""namesSnapshot"":[],""currentNames"":[]},""sheets"""&":{""3D8DE36231C"":{""name"":""3D8DE36231C"",""isDefaultCurrency"":true,""effectiveCurrencySymbol"":""$"",""selectedCurrencySymbol"":""$"",""hasUserOverriddenRate"":false,""isRateRowHidden"":true,""hasRedFormattingActive"":false,""currencyFormatRanges"":["&"""C3"",""C10:C"",""C5"",""C6"",""C7""],""taxTipDiscValues"":[""$0.00"",""$0.00"",""$0.00""],""splitSheetRows"":null},""3D8DE36231C"":{""name"":""3D8DE36231C"",""isDefaultCurrency"":true,""effectiveCurrencySymbol"":""$"",""selectedCurrencySymbol"":""$"","""&"hasUserOverriddenRate"":false,""isRateRowHidden"":true,""hasRedFormattingActive"":false,""currencyFormatRanges"":[""C3"",""C10:C"",""C5"",""C6"",""C7""],""taxTipDiscValues"":[""$0.00"",""$0.00"",""$0.00""],""splitSheetRows"":null},""Expenses"":{""name"":"&"""Expenses"",""isDefaultCurrency"":true,""effectiveCurrencySymbol"":""$"",""selectedCurrencySymbol"":""$"",""hasUserOverriddenRate"":false,""isRateRowHidden"":true,""hasRedFormattingActive"":false,""currencyFormatRanges"":[""C3"",""C10:C"",""C5"",""C6"","&"""C7""],""taxTipDiscValues"":[""$0.00"",""$0.00"",""$0.00""],""splitSheetRows"":null}}}") -> {"mainCurrencySymbol":"$","selectedMainCurrencySymbol":"$","splitSheetTitle":"Copy of Blank","maxRows":17,"maxColumns":22,"maxColWithData":13,"isSheetsFormulaStale":false,"people":{"namesSnapshot":[],"currentNames":[]},"sheets":{"3D8DE36231C":{"name":"3D8DE36231C","isDefaultCurrency":true,"effectiveCurrencySymbol":"$","selectedCurrencySymbol":"$","hasUserOverriddenRate":false,"isRateRowHidden":true,"hasRedFormattingActive":false,"currencyFormatRanges":["C3","C10:C","C5","C6","C7"],"taxTipDiscValues":["$0.00","$0.00","$0.00"],"splitSheetRows":null},"3D8DE36231C":{"name":"3D8DE36231C","isDefaultCurrency":true,"effectiveCurrencySymbol":"$","selectedCurrencySymbol":"$","hasUserOverriddenRate":false,"isRateRowHidden":true,"hasRedFormattingActive":false,"currencyFormatRanges":["C3","C10:C","C5","C6","C7"],"taxTipDiscValues":["$0.00","$0.00","$0.00"],"splitSheetRows":null},"Expenses":{"name":"Expenses","isDefaultCurrency":true,"effectiveCurrencySymbol":"$","selectedCurrencySymbol":"$","hasUserOverriddenRate":false,"isRateRowHidden":true,"hasRedFormattingActive":false,"currencyFormatRanges":["C3","C10:C","C5","C6","C7"],"taxTipDiscValues":["$0.00","$0.00","$0.00"],"splitSheetRows":null}}} | M5: =IFERROR(__xludf.DUMMYFUNCTION(" ArrayFormula(ROUND( BYCOL( EXPAND_TO_LAST_NAME_COL(M7:M17), LAMBDA( col, LET( header, INDEX(col, 1), IF(header="""",,LET( splits, OFFSET(col, 3, 0), explicitAssignments, Map(SPLITSHEET_"&"COL($C:$C),Lambda(it,Indirect(REGEXREPLACE(it,""F\d+$"", ""ExplicitPayers"")))), SUM(SPLITSHEET_COL($H:$H) * TRUNC(splits) - SPLITSHEET_COL($G:$G) * IF( IsBlank(explicitAssignments), MOD(splits"&", 1) * 10, Map(explicitAssignments,Lambda(eAssignment,IF( COUNTIF( TRIM(SPLIT(eAssignment, "","")), header ) > 0,1,0))) )) "&" ))) ) ), 3 ))"),0.0) -> 0
E6: Group: | J6: Disclaimer | M6: {=Transpose(LET( rng, EXPAND_TO_LAST_NAME_COL(M5), IF( AND(Counta(rng)>2,SUMPRODUCT(N(ISERROR(rng))) = 0,Sum(SPLITSHEET_COL(I:I))>0), GetAssignedTransactionGroups(rng), ) ))}
A7: =If(I3,"Refresh","Add Sheet") -> Add Sheet | D7: Item | E7: Amount | G7: Unit Paid | H7: Unit Cost | I7: Pay Units | J7: Cost Units | K7: =COUNTA(SPLITSHEET_COL($K:K)) -> 0 | L7: ref split vals | M7: {=LET( lastRow, MAX(IF(LEN(People!A:A), ROW(People!A:A))), items, If(lastRow=1,, TRANSPOSE(INDEX(People!A:A, 2):INDEX(People!A:A, lastRow))), items )}
A9: =IFERROR(__xludf.DUMMYFUNCTION("ADD_EMPTY_ROW(ARRAYFORMULA(iferror(REGEXEXTRACT(SPLITSHEET_COL($C:C),""^[^!]+""),)))"),"") | B9: =IFERROR(__xludf.DUMMYFUNCTION("ADD_EMPTY_ROW(MAP(SPLITSHEET_COL($C:$C), LAMBDA(c, IfError(LET( sn, REGEXEXTRACT(c, ""^[^!]+""), pairs, {""Tx""&UNICHAR(8239),""D5"";""Tp"",""D6"";""Dis""&UNICHAR(8239),""D7""}, TEXTJOIN("" - "", TRUE, BYROW(pairs, LAMBDA(rw, L"&"ET( title, INDEX(rw,1,1), addr, INDEX(rw,1,2), val, Round(INDIRECT(sn & ""!"" & addr),2), if(val>0,title & "": "" & TEXT(val, ""#,##0""""""&UNICHAR(8239)&"""""".00""),"""") ) )) ) ),) )))"),"") | C9: {=ADD_EMPTY_ROW(IF(_xlfn.ISFORMULA(D9), LET( sheetNames, GETSHEETNAMES(D9,false), IF(COUNTA(sheetNames)=0,, REDUCE(, sheetNames, LAMBDA(acc, sheet, LET( range, INDIRECT(sheet&"!A:A"), maxRow, LAST_ROW(range), refs, IF(maxRow>=G3, sheet&"!F"&SEQUENCE(maxRow-G3+1,1,G3),), IF(acc="", refs, VSTACK(acc, refs)) ) )) ) ), ))} | D9: =IFERROR(__xludf.DUMMYFUNCTION("ADD_EMPTY_ROW(Let(sheetNames, {'3D8DE36231C'!A1,Expenses!A1}, range0, Let(lastRow,LAST_ROW(EXPENSESHEET_COL('3D8DE36231C'!A:A)),If(lastRow>0,ChooseCols(Index('3D8DE36231C'!A:A,10):Index('3D8DE36231C'!E:E,lastRow),1,5,4),)), cond0, IfError('3D8DE36231C'!"&"Total>0,FALSE), array0, {ARRAYFORMULA(SEQUENCE(ROWS(range0),1,1,0)*0 + cond0 = 1), range0}, range1, Let(lastRow,LAST_ROW(EXPENSESHEET_COL(Expenses!A:A)),If(lastRow>0,ChooseCols(Index(Expenses!A:A,10):Index(Expenses!E:E,lastRow),1,5,4),)), cond1, IfErro"&"r(Expenses!Total>0,FALSE), array1, {ARRAYFORMULA(SEQUENCE(ROWS(range1),1,1,0)*0 + cond1 = 1), range1}, s, VSTACK(array0,array1), kept, FILTER(s, CHOOSECOLS(s, 1)), result,CHOOSECOLS(kept, 2, 3, 4), If(IsError(result),If(H2<>J2,{""Calculating..."",I"&"f(IsBlank(H2),""❓ ⇄ 💶"",""💵 ⇄ 💶"")},),result)))"),"") | G9: {=ADD_EMPTY_ROW(iferror(if(SPLITSHEET_COL($E:$E)="",,(SPLITSHEET_COL($E:$E)+SPLITSHEET_COL($F:$F))/SPLITSHEET_COL($I:$I)),0))} | H9: {=ADD_EMPTY_ROW(Let(colE,SPLITSHEET_COL($E:$E),sum,SPLITSHEET_COL($F:F)+colE,if(sum=0,,(sum/SPLITSHEET_COL($J:$J)))))} | I9: =IFERROR(__xludf.DUMMYFUNCTION("LET( rows, BYROW( ARRAYFORMULA(EXPAND_TO_LAST_NAME_COL(SPLITSHEET_COL(M:M))), LAMBDA( splitRow, LET( payRatios, ARRAYFORMULA(MOD(splitRow, 1) * 10), billSheetName, REGEXEXTRACT(INDEX($C:$C, ROW(splitRo"&"w)), ""^[^!]+""), explicitAssignments, INDIRECT(billSheetName & ""!ExplicitPayers""), IF( ISERROR(billSheetName), , IF( ISBLANK(explicitAssignments), SUM(payRatios), "&" COUNTA(SPLIT(explicitAssignments, "","")) ) ) ) ) ), total, SUM(rows), VSTACK(total, rows) )"),0.0) -> 0 | J9: {=ADD_EMPTY_ROW(BYROW(EXPAND_TO_LAST_NAME_COL(SPLITSHEET_COL(M:M)), LAMBDA(rw, Let(result,Sum(Trunc(rw)),if(AND(result>0,Not(IsBlank(Indirect("E"& Row(rw))))),result,)))))} | K9: =IFERROR(__xludf.DUMMYFUNCTION("ADD_EMPTY_ROW(ArrayFormula( IF(LEN(SPLITSHEET_COL(C:C)) > 0, IF(REGEXMATCH( BYROW(Offset(SPLITSHEET_COL(M:M),0,0,,L3-Column(M1)+1), LAMBDA(row, JOIN("","", row))), ""^"" & SUBSTITUTE(REGEXREPLACE(SPLITSHEET_COL(L:L), "",+$"", ), """&"."", ""\."") & "",*$"" ), , 1 ), ) ))"),"") | L9: =IFERROR(__xludf.DUMMYFUNCTION("ADD_EMPTY_ROW( LET( colC, SPLITSHEET_COL(C:C), countC, COUNTA(colC), IF( countC = 0,, ARRAYFORMULA( REGEXEXTRACT( MAP( ARRAY_CONSTRAIN(colC, countC, 1), LAMBDA(addr, INDIRECT(addr)) "&" ),""(?:[^,]*(?:,)){0,"" & ($L$3 - 1 - 12) & ""}[^,]*"" ) ) ) ) )"),"")

Sheet People
A1: Names | B1: []

Sheet Expenses
A1: =If(F1<>E1,"⏳ ",) & "Currency:" -> Currency: | B1: {={"",Currencies!A1}} | C1: Default | D1: {=If(D2,{SelectedMainCurrencyAbbr,SelectedMainCurrencySymbol},XLookup(C1,Currencies!A:A,Currencies!B:C))} -> USD | E1: $ | F1: =IFERROR(__xludf.DUMMYFUNCTION("RegExExtract(TO_TEXT(C3),""^\s*([^0-9\s]+)\s*\d{1,3}(?:,\d{3})*\.\d{2}"")"),"$") -> $
A2: =IF(IsError(B2),2,1) -> 1 | B2: {={ "", If(D2,1,IfError(1/XLookup(D1,Currencies!I:I,Currencies!J:J),Exchange_Rate(D1,SelectedMainCurrencyAbbr,Today()))) }} | C2: 1 | D2: =C1=Currencies!A1 -> TRUE | E2: 10 | F2: =Not(SUBTOTAL(103, E2)) -> TRUE
A3: Total: | C3: =Round(Sum(EXPENSESHEET_COL(C:C))+ E5 + E6 - E7,2) -> 0 | F3: =IFERROR(__xludf.DUMMYFUNCTION("OR(OR(ARRAYFORMULA(COUNTIF(Indirect(""$A$8:$A""),$A10:$A19) >1)),OR(ARRAYFORMULA((((Not(IsBlank($A10:$A19)))*(IsBlank($C10:$C19)))>0))),OR(ARRAYFORMULA((((IsBlank($A10:$A19))*(Not(IsBlank($C10:$C19))))>0))),COUNTIF(INDIRECT(""Currencies!F:F""), C1) = 0,("&"((C4<>"""")*(SUMPRODUCT(COUNTIF(INDIRECT(""People!A2:A""),TRIM(SPLIT(SUBSTITUTE(C4,"""""""",""""),"","")))=0)>0))>0))"),FALSE) -> FALSE
A4: Paid By: | F4: =CountA(A10:A100000001) -> 0
A5: =IFERROR(__xludf.DUMMYFUNCTION("ArrayFormula(Let(n,Now(),textValue,TO_TEXT($C5:$C7),sumOfC,Sum(EXPENSESHEET_COL(C:C)),If(RegExMatch(textValue,""^((\s*\d+(\.\d*)?\s*)|(0%))$""),""⏳ "",) & {""Tax: "";""Tip: "";""Discount: ""} & If(sumOfC=0,"""",If($E5:$E7=0,"""",""(""& If(REGEXMATCH(te"&"xtValue, ""%"") ,Text($E5:$E7,""""""""& F1 & """"""##0.00""),Text(Round($E5:$E7/sumOfC,2),""0.00%""))&"")""))))"),"Tax: ") -> Tax: | B5: ={"",0} | C5: 0 | D5: {=E5:E7*$C$2} -> 0 | E5: =IFERROR(__xludf.DUMMYFUNCTION("ARRAYFORMULA(LET( n,Now(), vals, $C5:$C6, txt, TO_TEXT(vals), total, SUM(EXPENSESHEET_COL(C:C)), IF(REGEXMATCH(txt, ""%""), vals * total, vals ) ) )"),0.0) -> 0
A6: =IFERROR(__xludf.DUMMYFUNCTION("""COMPUTED_VALUE"""),"Tip: ") -> Tip: | B6: ={"",0} | C6: 0 | D6: 0 | E6: =IFERROR(__xludf.DUMMYFUNCTION("""COMPUTED_VALUE"""),0.0) -> 0
A7: =IFERROR(__xludf.DUMMYFUNCTION("""COMPUTED_VALUE"""),"Discount: ") -> Discount: | B7: ={"",0} | C7: 0 | D7: 0 | E7: =IFERROR(__xludf.DUMMYFUNCTION("LET( n,Now(), val, $C7, txt, TO_TEXT(val), total, SUM(EXPENSESHEET_COL(C:C)), amount,IF(REGEXMATCH(txt, ""%""), val * total, val ), Min(total,amount) ) "),0.0) -> 0
A8: Item | C8: Amount
D9: {=If(IsBlank($C$9:$C19)+($C$9:$C19=0),,Let(itemSum,SUM($C$9:$C19),if(itemSum=0,0,(($D$5+$D$6 - MIN(itemSum,$D$7))/itemSum) * $C$9:$C19*$C$2)))} | E9: {=If(IsBlank(C9:C19),,C9:C19*$C$2)}

Sheet Currencies
A1: Default | D1: {="("&B:B&")"&REPT(" ", 20)&A:A} -> () Default | F1: =IFERROR(__xludf.DUMMYFUNCTION("LET( data, FILTER(A:B, B:B<>SelectedMainCurrencyAbbr), sheetNames, GETSHEETNAMES(Split!D9, TRUE), usedCurrencies, UNIQUE( TOCOL( MAP( sheetNames, LAMBDA(s, INDIRECT(s & ""!C1"")) ), 1 ) "&" ), priority, MAP( INDEX(data,,1), LAMBDA(cur, IF( cur=""Default"", 0, IF(COUNTIF(usedCurrencies, cur), 1, 2) ) ) ), SORT( data, priority, TRUE, SEQUENCE(ROWS(data)), "&"TRUE ) )"),"Default") -> Default | I1: =EXCHANGE_RATE_TO(SelectedMainCurrencyAbbr, SelectedMainCurrencyAbbr,Today()) -> 1inch | J1: 12.256166
A2: US Dollar | B2: USD | C2: $ | D2: (USD) US Dollar | F2: =IFERROR(__xludf.DUMMYFUNCTION("""COMPUTED_VALUE"""),"Euro") -> Euro | G2: =IFERROR(__xludf.DUMMYFUNCTION("""COMPUTED_VALUE"""),"EUR") -> EUR | I2: aave | J2: 0.010838161
A3: Euro | B3: EUR | C3: € | D3: (EUR) Euro | F3: =IFERROR(__xludf.DUMMYFUNCTION("""COMPUTED_VALUE"""),"Afghan Afghani") -> Afghan Afghani | G3: =IFERROR(__xludf.DUMMYFUNCTION("""COMPUTED_VALUE"""),"AFN") -> AFN | I3: ada | J3: 5.8786785
A4: Afghan Afghani | B4: AFN | C4: ؋ | D4: (AFN) Afghan Afghani | F4: =IFERROR(__xludf.DUMMYFUNCTION("""COMPUTED_VALUE"""),"Albanian Lek") -> Albanian Lek | G4: =IFERROR(__xludf.DUMMYFUNCTION("""COMPUTED_VALUE"""),"ALL") -> ALL | I4: aed | J4: 3.6725
A5: Albanian Lek | B5: ALL | C5: L | D5: (ALL) Albanian Lek | F5: =IFERROR(__xludf.DUMMYFUNCTION("""COMPUTED_VALUE"""),"Algerian Dinar") -> Algerian Dinar | G5: =IFERROR(__xludf.DUMMYFUNCTION("""COMPUTED_VALUE"""),"DZD") -> DZD | I5: afn | J5: 65.917585
A6: Algerian Dinar | B6: DZD | C6: دج | D6: (DZD) Algerian Dinar | F6: =IFERROR(__xludf.DUMMYFUNCTION("""COMPUTED_VALUE"""),"Algorand") -> Algorand | G6: =IFERROR(__xludf.DUMMYFUNCTION("""COMPUTED_VALUE"""),"ALGO") -> ALGO | I6: agix | J6: 16.357288
A7: Algorand | B7: ALGO | C7: ALGO | D7: (ALGO) Algorand | F7: =IFERROR(__xludf.DUMMYFUNCTION("""COMPUTED_VALUE"""),"Angolan Kwanza") -> Angolan Kwanza | G7: =IFERROR(__xludf.DUMMYFUNCTION("""COMPUTED_VALUE"""),"AOA") -> AOA | I7: akt | J7: 2.2731789
A8: Angolan Kwanza | B8: AOA | C8: Kz | D8: (AOA) Angolan Kwanza | F8: =IFERROR(__xludf.DUMMYFUNCTION("""COMPUTED_VALUE"""),"Argentine Peso") -> Argentine Peso | G8: =IFERROR(__xludf.DUMMYFUNCTION("""COMPUTED_VALUE"""),"ARS") -> ARS | I8: algo | J8: 12.576856
A9: Argentine Peso | B9: ARS | C9: $ | D9: (ARS) Argentine Peso | F9: =IFERROR(__xludf.DUMMYFUNCTION("""COMPUTED_VALUE"""),"Armenian Dram") -> Armenian Dram | G9: =IFERROR(__xludf.DUMMYFUNCTION("""COMPUTED_VALUE"""),"AMD") -> AMD | I9: all | J9: 81.184056
A10: Armenian Dram | B10: AMD | C10: ֏ | D10: (AMD) Armenian Dram | F10: =IFERROR(__xludf.DUMMYFUNCTION("""COMPUTED_VALUE"""),"Aruban or Dutch Guilder") -> Aruban or Dutch Guilder | G10: =IFERROR(__xludf.DUMMYFUNCTION("""COMPUTED_VALUE"""),"AWG") -> AWG | I10: amd | J10: 365.6928
A11: Aruban or Dutch Guilder | B11: AWG | C11: ƒ | D11: (AWG) Aruban or Dutch Guilder | F11: =IFERROR(__xludf.DUMMYFUNCTION("""COMPUTED_VALUE"""),"Australian Dollar") -> Australian Dollar | G11: =IFERROR(__xludf.DUMMYFUNCTION("""COMPUTED_VALUE"""),"AUD") -> AUD | I11: amp | J11: 2545.981
A12: Australian Dollar | B12: AUD | C12: $ | D12: (AUD) Australian Dollar | F12: =IFERROR(__xludf.DUMMYFUNCTION("""COMPUTED_VALUE"""),"Azerbaijan Manat") -> Azerbaijan Manat | G12: =IFERROR(__xludf.DUMMYFUNCTION("""COMPUTED_VALUE"""),"AZN") -> AZN | I12: ang | J12: 1.797023
A13: Azerbaijan Manat | B13: AZN | C13: ₼ | D13: (AZN) Azerbaijan Manat | F13: =IFERROR(__xludf.DUMMYFUNCTION("""COMPUTED_VALUE"""),"Bahamian Dollar") -> Bahamian Dollar | G13: =IFERROR(__xludf.DUMMYFUNCTION("""COMPUTED_VALUE"""),"BSD") -> BSD | I13: aoa | J13: 915.96127
A14: Bahamian Dollar | B14: BSD | C14: $ | D14: (BSD) Bahamian Dollar | F14: =IFERROR(__xludf.DUMMYFUNCTION("""COMPUTED_VALUE"""),"Bahraini Dinar") -> Bahraini Dinar | G14: =IFERROR(__xludf.DUMMYFUNCTION("""COMPUTED_VALUE"""),"BHD") -> BHD | I14: ape | J14: 7.4485307
A15: Bahraini Dinar | B15: BHD | C15: د.ب | D15: (BHD) Bahraini Dinar | F15: =IFERROR(__xludf.DUMMYFUNCTION("""COMPUTED_VALUE"""),"Bangladeshi Taka") -> Bangladeshi Taka | G15: =IFERROR(__xludf.DUMMYFUNCTION("""COMPUTED_VALUE"""),"BDT") -> BDT | I15: apt | J15: 1.7897832
A16: Bangladeshi Taka | B16: BDT | C16: ৳ | D16: (BDT) Bangladeshi Taka | F16: =IFERROR(__xludf.DUMMYFUNCTION("""COMPUTED_VALUE"""),"Barbadian or Bajan Dollar") -> Barbadian or Bajan Dollar | G16: =IFERROR(__xludf.DUMMYFUNCTION("""COMPUTED_VALUE"""),"BBD") -> BBD | I16: ar | J16: 0.57600434
A17: Barbadian or Bajan Dollar | B17: BBD | C17: $ | D17: (BBD) Barbadian or Bajan Dollar | F17: =IFERROR(__xludf.DUMMYFUNCTION("""COMPUTED_VALUE"""),"Belarusian Ruble") -> Belarusian Ruble | G17: =IFERROR(__xludf.DUMMYFUNCTION("""COMPUTED_VALUE"""),"BYN") -> BYN | I17: arb | J17: 12.808749
A18: Belarusian Ruble | B18: BYN | C18: Br | D18: (BYN) Belarusian Ruble | F18: =IFERROR(__xludf.DUMMYFUNCTION("""COMPUTED_VALUE"""),"Belarusian Ruble") -> Belarusian Ruble | G18: =IFERROR(__xludf.DUMMYFUNCTION("""COMPUTED_VALUE"""),"BYR") -> BYR | I18: ars | J18: 1486.0305
A19: Belarusian Ruble | B19: BYR | C19: Br | D19: (BYR) Belarusian Ruble | F19: =IFERROR(__xludf.DUMMYFUNCTION("""COMPUTED_VALUE"""),"Belizean Dollar") -> Belizean Dollar | G19: =IFERROR(__xludf.DUMMYFUNCTION("""COMPUTED_VALUE"""),"BZD") -> BZD | I19: atom | J19: 0.81383818
A20: Belizean Dollar | B20: BZD | C20: BZ$ | D20: (BZD) Belizean Dollar | F20: =IFERROR(__xludf.DUMMYFUNCTION("""COMPUTED_VALUE"""),"Bermudian Dollar") -> Bermudian Dollar | G20: =IFERROR(__xludf.DUMMYFUNCTION("""COMPUTED_VALUE"""),"BMD") -> BMD | I20: ats | J20: 11.93524
A21: Bermudian Dollar | B21: BMD | C21: $ | D21: (BMD) Bermudian Dollar | F21: =IFERROR(__xludf.DUMMYFUNCTION("""COMPUTED_VALUE"""),"Bhutanese Ngultrum") -> Bhutanese Ngultrum | G21: =IFERROR(__xludf.DUMMYFUNCTION("""COMPUTED_VALUE"""),"BTN") -> BTN | I21: aud | J21: 1.421997
A22: Bhutanese Ngultrum | B22: BTN | C22: Nu. | D22: (BTN) Bhutanese Ngultrum | F22: =IFERROR(__xludf.DUMMYFUNCTION("""COMPUTED_VALUE"""),"Bitcoin") -> Bitcoin | G22: =IFERROR(__xludf.DUMMYFUNCTION("""COMPUTED_VALUE"""),"BTC") -> BTC | I22: avax | J22: 0.15638769
A23: Bitcoin | B23: BTC | C23: ₿ | D23: (BTC) Bitcoin | F23: =IFERROR(__xludf.DUMMYFUNCTION("""COMPUTED_VALUE"""),"Bolivian Bolíviano") -> Bolivian Bolíviano | G23: =IFERROR(__xludf.DUMMYFUNCTION("""COMPUTED_VALUE"""),"BOB") -> BOB | I23: awg | J23: 1.79
A24: Bolivian Bolíviano | B24: BOB | C24: Bs. | D24: (BOB) Bolivian Bolíviano | F24: =IFERROR(__xludf.DUMMYFUNCTION("""COMPUTED_VALUE"""),"Bosnian Convertible Mark") -> Bosnian Convertible Mark | G24: =IFERROR(__xludf.DUMMYFUNCTION("""COMPUTED_VALUE"""),"BAM") -> BAM | I24: axs | J24: 1.1938483
A25: Bosnian Convertible Mark | B25: BAM | C25: KM | D25: (BAM) Bosnian Convertible Mark | F25: =IFERROR(__xludf.DUMMYFUNCTION("""COMPUTED_VALUE"""),"Botswana Pula") -> Botswana Pula | G25: =IFERROR(__xludf.DUMMYFUNCTION("""COMPUTED_VALUE"""),"BWP") -> BWP | I25: azm | J25: 8499.9963
A26: Botswana Pula | B26: BWP | C26: P | D26: (BWP) Botswana Pula | F26: =IFERROR(__xludf.DUMMYFUNCTION("""COMPUTED_VALUE"""),"Brazilian Real") -> Brazilian Real | G26: =IFERROR(__xludf.DUMMYFUNCTION("""COMPUTED_VALUE"""),"BRL") -> BRL | I26: azn | J26: 1.6999993
A27: Brazilian Real | B27: BRL | C27: R$ | D27: (BRL) Brazilian Real | F27: =IFERROR(__xludf.DUMMYFUNCTION("""COMPUTED_VALUE"""),"British Pound") -> British Pound | G27: =IFERROR(__xludf.DUMMYFUNCTION("""COMPUTED_VALUE"""),"GBP") -> GBP | I27: bake | J27: 1402.9848
A28: British Pound | B28: GBP | C28: £ | D28: (GBP) British Pound | F28: =IFERROR(__xludf.DUMMYFUNCTION("""COMPUTED_VALUE"""),"Bruneian Dollar") -> Bruneian Dollar | G28: =IFERROR(__xludf.DUMMYFUNCTION("""COMPUTED_VALUE"""),"BND") -> BND | I28: bam | J28: 1.6964238
A29: Bruneian Dollar | B29: BND | C29: $ | D29: (BND) Bruneian Dollar | F29: =IFERROR(__xludf.DUMMYFUNCTION("""COMPUTED_VALUE"""),"Bulgarian Lev") -> Bulgarian Lev | G29: =IFERROR(__xludf.DUMMYFUNCTION("""COMPUTED_VALUE"""),"BGN") -> BGN | I29: bat | J29: 15.22414
A30: Bulgarian Lev | B30: BGN | C30: лв | D30: (BGN) Bulgarian Lev | F30: =IFERROR(__xludf.DUMMYFUNCTION("""COMPUTED_VALUE"""),"Burmese Kyat") -> Burmese Kyat | G30: =IFERROR(__xludf.DUMMYFUNCTION("""COMPUTED_VALUE"""),"MMK") -> MMK | I30: bbd | J30: 2
A31: Burmese Kyat | B31: MMK | C31: K | D31: (MMK) Burmese Kyat | F31: =IFERROR(__xludf.DUMMYFUNCTION("""COMPUTED_VALUE"""),"Burundian Franc") -> Burundian Franc | G31: =IFERROR(__xludf.DUMMYFUNCTION("""COMPUTED_VALUE"""),"BIF") -> BIF | I31: bch | J31: 0.0047301105
A32: Burundian Franc | B32: BIF | C32: FBu | D32: (BIF) Burundian Franc | F32: =IFERROR(__xludf.DUMMYFUNCTION("""COMPUTED_VALUE"""),"Cambodian Riel") -> Cambodian Riel | G32: =IFERROR(__xludf.DUMMYFUNCTION("""COMPUTED_VALUE"""),"KHR") -> KHR | I32: bdt | J32: 123.36114
A33: Cambodian Riel | B33: KHR | C33: ៛ | D33: (KHR) Cambodian Riel | F33: =IFERROR(__xludf.DUMMYFUNCTION("""COMPUTED_VALUE"""),"Canadian Dollar") -> Canadian Dollar | G33: =IFERROR(__xludf.DUMMYFUNCTION("""COMPUTED_VALUE"""),"CAD") -> CAD | I33: bef | J33: 34.989527
A34: Canadian Dollar | B34: CAD | C34: $ | D34: (CAD) Canadian Dollar | F34: =IFERROR(__xludf.DUMMYFUNCTION("""COMPUTED_VALUE"""),"Cape Verdean Escudo") -> Cape Verdean Escudo | G34: =IFERROR(__xludf.DUMMYFUNCTION("""COMPUTED_VALUE"""),"CVE") -> CVE | I34: bgn | J34: 1.6964238
A35: Cape Verdean Escudo | B35: CVE | C35: $ | D35: (CVE) Cape Verdean Escudo | F35: =IFERROR(__xludf.DUMMYFUNCTION("""COMPUTED_VALUE"""),"Cardano") -> Cardano | G35: =IFERROR(__xludf.DUMMYFUNCTION("""COMPUTED_VALUE"""),"ADA") -> ADA | I35: bhd | J35: 0.376
A36: Cardano | B36: ADA | C36: ₳ | D36: (ADA) Cardano | F36: =IFERROR(__xludf.DUMMYFUNCTION("""COMPUTED_VALUE"""),"Caymanian Dollar") -> Caymanian Dollar | G36: =IFERROR(__xludf.DUMMYFUNCTION("""COMPUTED_VALUE"""),"KYD") -> KYD | I36: bif | J36: 2957.589
A37: Caymanian Dollar | B37: KYD | C37: $ | D37: (KYD) Caymanian Dollar | F37: =IFERROR(__xludf.DUMMYFUNCTION("""COMPUTED_VALUE"""),"Central African CFA Franc BEAC") -> Central African CFA Franc BEAC | G37: =IFERROR(__xludf.DUMMYFUNCTION("""COMPUTED_VALUE"""),"XAF") -> XAF | I37: bmd | J37: 1
A38: Central African CFA Franc BEAC | B38: XAF | C38: CFA | D38: (XAF) Central African CFA Franc BEAC | F38: =IFERROR(__xludf.DUMMYFUNCTION("""COMPUTED_VALUE"""),"CFA Franc") -> CFA Franc | G38: =IFERROR(__xludf.DUMMYFUNCTION("""COMPUTED_VALUE"""),"XOF") -> XOF | I38: bnb | J38: 0.0016979747
A39: CFA Franc | B39: XOF | C39: CFA | D39: (XOF) CFA Franc | F39: =IFERROR(__xludf.DUMMYFUNCTION("""COMPUTED_VALUE"""),"CFP Franc") -> CFP Franc | G39: =IFERROR(__xludf.DUMMYFUNCTION("""COMPUTED_VALUE"""),"XPF") -> XPF | I39: bnd | J39: 1.2820822
A40: CFP Franc | B40: XPF | C40: ₣ | D40: (XPF) CFP Franc | F40: =IFERROR(__xludf.DUMMYFUNCTION("""COMPUTED_VALUE"""),"Chainlink") -> Chainlink | G40: =IFERROR(__xludf.DUMMYFUNCTION("""COMPUTED_VALUE"""),"LINK") -> LINK | I40: bob | J40: 12.014497
...

Sheet 3D8DE36231C
A1: =If(F1<>E1,"⏳ ",) & "Currency:" -> Currency: | B1: {={"",Currencies!A1}} -> #REF! | C1: Default | D1: {=If(D2,{SelectedMainCurrencyAbbr,SelectedMainCurrencySymbol},XLookup(C1,Currencies!A:A,Currencies!B:C))} -> USD | E1: $ | F1: =IFERROR(__xludf.DUMMYFUNCTION("RegExExtract(TO_TEXT(C3),""^\s*([^0-9\s]+)\s*\d{1,3}(?:,\d{3})*\.\d{2}"")"),"$") -> $
A2: =IF(IsError(B2),2,1) -> 1 | B2: {={ "", If(D2,1,IfError(1/XLookup(D1,Currencies!I:I,Currencies!J:J),Exchange_Rate(D1,SelectedMainCurrencyAbbr,Today()))) }} | C2: 1 | D2: =C1=Currencies!A1 -> TRUE | E2: 10 | F2: =Not(SUBTOTAL(103, E2)) -> TRUE
A3: Total: | C3: =Round(Sum(EXPENSESHEET_COL(C:C))+ E5 + E6 - E7,2) -> 0 | F3: =IFERROR(__xludf.DUMMYFUNCTION("OR(OR(ARRAYFORMULA(COUNTIF(Indirect(""$A$8:$A""),$A10:$A19) >1)),OR(ARRAYFORMULA((((Not(IsBlank($A10:$A19)))*(IsBlank($C10:$C19)))>0))),OR(ARRAYFORMULA((((IsBlank($A10:$A19))*(Not(IsBlank($C10:$C19))))>0))),COUNTIF(INDIRECT(""Currencies!F:F""), C1) = 0,("&"((C4<>"""")*(SUMPRODUCT(COUNTIF(INDIRECT(""People!A2:A""),TRIM(SPLIT(SUBSTITUTE(C4,"""""""",""""),"","")))=0)>0))>0))"),FALSE) -> FALSE
A4: Paid By: | F4: =CountA(A10:A100000004) -> 0
A5: =IFERROR(__xludf.DUMMYFUNCTION("ArrayFormula(Let(n,Now(),textValue,TO_TEXT($C5:$C7),sumOfC,Sum(EXPENSESHEET_COL(C:C)),If(RegExMatch(textValue,""^((\s*\d+(\.\d*)?\s*)|(0%))$""),""⏳ "",) & {""Tax: "";""Tip: "";""Discount: ""} & If(sumOfC=0,"""",If($E5:$E7=0,"""",""(""& If(REGEXMATCH(te"&"xtValue, ""%"") ,Text($E5:$E7,""""""""& F1 & """"""##0.00""),Text(Round($E5:$E7/sumOfC,2),""0.00%""))&"")""))))"),"Tax: ") -> Tax: | B5: ={"",0} | C5: 0 | D5: {=E5:E7*$C$2} -> 0 | E5: =IFERROR(__xludf.DUMMYFUNCTION("ARRAYFORMULA(LET( n,Now(), vals, $C5:$C6, txt, TO_TEXT(vals), total, SUM(EXPENSESHEET_COL(C:C)), IF(REGEXMATCH(txt, ""%""), vals * total, vals ) ) )"),0.0) -> 0
A6: =IFERROR(__xludf.DUMMYFUNCTION("""COMPUTED_VALUE"""),"Tip: ") -> Tip: | B6: ={"",0} | C6: 0 | D6: 0 | E6: =IFERROR(__xludf.DUMMYFUNCTION("""COMPUTED_VALUE"""),0.0) -> 0
A7: =IFERROR(__xludf.DUMMYFUNCTION("""COMPUTED_VALUE"""),"Discount: ") -> Discount: | B7: ={"",0} | C7: 0 | D7: 0 | E7: =IFERROR(__xludf.DUMMYFUNCTION("LET( n,Now(), val, $C7, txt, TO_TEXT(val), total, SUM(EXPENSESHEET_COL(C:C)), amount,IF(REGEXMATCH(txt, ""%""), val * total, val ), Min(total,amount) ) "),0.0) -> 0
A8: Item | C8: Amount
D9: {=If(IsBlank($C$9:$C19)+($C$9:$C19=0),,Let(itemSum,SUM($C$9:$C19),if(itemSum=0,0,(($D$5+$D$6 - MIN(itemSum,$D$7))/itemSum) * $C$9:$C19*$C$2)))} | E9: {=If(IsBlank(C9:C19),,C9:C19*$C$2)}
